<?xml version="1.0"?>
<robot xmlns:xacro="http://ros.org/wiki/xacro" name="510_mm_sensor_arch">

    <xacro:macro name="sensor_arch" params="prefix parent size:=510 *origin">

        <!-- Spawn the sensor arch link -->
        <link name="${prefix}sensor_arch_mount_link">
             <origin xyz="0 0 0" rpy="0 0 0"/>
             <visual>
		<origin xyz="0 0 -0.27" rpy="0 0 0"/>
                 <!--geometry>
                     <mesh filename="package://husky_description/meshes/accessories/${size}_mm_sensor_arch.dae" />
                 </geometry-->
		  <geometry>
		   <cylinder radius="0.05" length="0.48"/>
		  </geometry>
	       	<material name="black"/>
             </visual>
             <!--collision>
                 <origin xyz="0 0 0" rpy="0 0 0"/>
                 <geometry>
                     <mesh filename="package://husky_description/meshes/accessories/${size}_mm_sensor_arch.dae" />
                 </geometry>
             </collision-->
        </link>

	  <gazebo reference="${prefix}sensor_arch_mount_link">
	    <mu1>0</mu1>
	    <mu2>0</mu2>
	    <material>Gazebo/Black</material>
	  </gazebo>

        <!-- Attach the sensor arch to the top plate -->
        <joint name="${prefix}sensor_arch_mount_joint" type="revolute">
             <xacro:insert_block name="origin"/>
             <parent link="${parent}"/>
             <child link="${prefix}sensor_arch_mount_link"/>
		 <axis xyz="0 0 1"/>
		 <limit effort="50" velocity="10.0" lower="${-M_PI/2}" upper="${M_PI/2}" />
		 <dynamics damping="0.0" friction="0.0"/>
        </joint>

	<transmission name="${prefix}sensor_arch_mount_trans" type="SimpleTransmission">
		<type>transmission_interface/SimpleTransmission</type>
		<actuator name="${prefix}sensor_arch_mount_motor">
			<mechanicalReduction>1</mechanicalReduction>
		</actuator>
		<joint name="${prefix}sensor_arch_mount_joint">
			<hardwareInterface>hardware_interface/PositionJointInterface</hardwareInterface>
		</joint>
	</transmission>

	<!--gazebo>
		<plugin name="object_controller" filename="libgazebo_ros_planar_move.so">
			<commandTopic>cmd_kinect</commandTopic>
			<odometryTopic>odom</odometryTopic>
			<odometryFrame>odom</odometryFrame>
			<odometryRate>20.0</odometryRate>
			<robotBaseFrame>${prefix}sensor_arch_mount_link</robotBaseFrame>
		</plugin>
	</gazebo-->

    </xacro:macro>

</robot>
